Workbook

Sheet Dashboard
A1: Weight Management Food Tracker
A3: Daily Calorie Target | B3: 2000 | D3: Today | E3: Calories | F3: Protein | G3: Nutrition | H3: Items
A4: Protein Target (g) | B4: 100 | D4: =TODAY() -> 46201 | E4: =SUMIFS('Meal Log'!E:E,'Meal Log'!A:A,D4) -> 1015 | F4: =SUMIFS('Meal Log'!F:F,'Meal Log'!A:A,D4) -> 57 | G4: =IF(H4=0,"",ROUND(SUMIFS('Meal Log'!G:G,'Meal Log'!A:A,D4)/H4,1)) -> 8.7 | H4: =COUNTIF('Meal Log'!A:A,D4) -> 4
A5: Nutrition Score Target | B5: 7
A6: Goal Weight | B6: 170
A7: Current Weight | B7: =IFERROR(LOOKUP(2,1/('Weight Log'!B:B<>""),'Weight Log'!B:B),"")
A8: Weight to Goal | B8: =IF(B7="","",B7-B6)
A9: Last 7-Day Avg Calories | B9: =IFERROR(LOOKUP(2,1/('Daily Summary'!G:G<>""),'Daily Summary'!G:G),"") -> 7-Day Avg Calories
A12: How to use: add reusable foods/nicknames on the Foods tab, then log each meal on Meal Log. Daily Summary and Dashboard update automatically.

Sheet Meal Log
A1: Date | B1: Meal | C1: Food | D1: Quantity | E1: Calories | F1: Protein (g) | G1: Nutrition Points | H1: Notes | I1: Known Food?
A2: 46196 | B2: Breakfast | C2: Cereal with Whole Milk | D2: 1 | E2: =IF($C2="","",IFERROR($D2*VLOOKUP($C2,Foods!$A:$E,3,FALSE),"Add to Foods")) -> 400 | F2: =IF($C2="","",IFERROR($D2*VLOOKUP($C2,Foods!$A:$E,4,FALSE),"Add to Foods")) -> 12 | G2: =IF($C2="","",IFERROR($D2*VLOOKUP($C2,Foods!$A:$E,5,FALSE),"Add to Foods")) -> 6 | I2: =IF($C2="","",IF(COUNTIF(Foods!$A:$A,$C2)>0,"Yes","No - add nickname")) -> Yes
A3: 46196 | B3: Breakfast | C3: Blueberry Protein Shake | D3: 1 | E3: =IF($C3="","",IFERROR($D3*VLOOKUP($C3,Foods!$A:$E,3,FALSE),"Add to Foods")) -> 450 | F3: =IF($C3="","",IFERROR($D3*VLOOKUP($C3,Foods!$A:$E,4,FALSE),"Add to Foods")) -> 35 | G3: =IF($C3="","",IFERROR($D3*VLOOKUP($C3,Foods!$A:$E,5,FALSE),"Add to Foods")) -> 9 | I3: =IF($C3="","",IF(COUNTIF(Foods!$A:$A,$C3)>0,"Yes","No - add nickname")) -> Yes
A4: 46196 | B4: Lunch | C4: PB Banana Sandwich | D4: 1 | E4: =IF($C4="","",IFERROR($D4*VLOOKUP($C4,Foods!$A:$E,3,FALSE),"Add to Foods")) -> 500 | F4: =IF($C4="","",IFERROR($D4*VLOOKUP($C4,Foods!$A:$E,4,FALSE),"Add to Foods")) -> 18 | G4: =IF($C4="","",IFERROR($D4*VLOOKUP($C4,Foods!$A:$E,5,FALSE),"Add to Foods")) -> 7 | I4: =IF($C4="","",IF(COUNTIF(Foods!$A:$A,$C4)>0,"Yes","No - add nickname")) -> Yes
A5: 46196 | B5: Lunch | C5: Leafy greens salad w/cheese | D5: 1 | E5: =IF($C5="","",IFERROR($D5*VLOOKUP($C5,Foods!$A:$E,3,FALSE),"Add to Foods")) -> 60 | F5: =IF($C5="","",IFERROR($D5*VLOOKUP($C5,Foods!$A:$E,4,FALSE),"Add to Foods")) -> 1 | G5: =IF($C5="","",IFERROR($D5*VLOOKUP($C5,Foods!$A:$E,5,FALSE),"Add to Foods")) -> 9 | I5: =IF($C5="","",IF(COUNTIF(Foods!$A:$A,$C5)>0,"Yes","No - add nickname")) -> Yes
A6: 46196 | B6: Lunch | C6: Corn chips and salsa | D6: 1 | E6: =IF($C6="","",IFERROR($D6*VLOOKUP($C6,Foods!$A:$E,3,FALSE),"Add to Foods")) -> 180 | F6: =IF($C6="","",IFERROR($D6*VLOOKUP($C6,Foods!$A:$E,4,FALSE),"Add to Foods")) -> 3 | G6: =IF($C6="","",IFERROR($D6*VLOOKUP($C6,Foods!$A:$E,5,FALSE),"Add to Foods")) -> 4 | I6: Yes
A7: 46196 | B7: Snack | C7: Mixed Nuts & Raisins (1 cup) | D7: 1 | E7: =IF($C7="","",IFERROR($D7*VLOOKUP($C7,Foods!$A:$E,3,FALSE),"Add to Foods")) -> 650 | F7: =IF($C7="","",IFERROR($D7*VLOOKUP($C7,Foods!$A:$E,4,FALSE),"Add to Foods")) -> 18 | G7: =IF($C7="","",IFERROR($D7*VLOOKUP($C7,Foods!$A:$E,5,FALSE),"Add to Foods")) -> 6 | I7: =IF($C7="","",IF(COUNTIF(Foods!$A:$A,$C7)>0,"Yes","No - add nickname")) -> Yes
A8: 46196 | B8: Dinner | C8: Udon Bowl | D8: 1 | E8: =IF($C8="","",IFERROR($D8*VLOOKUP($C8,Foods!$A:$E,3,FALSE),"Add to Foods")) -> 700 | F8: =IF($C8="","",IFERROR($D8*VLOOKUP($C8,Foods!$A:$E,4,FALSE),"Add to Foods")) -> 20 | G8: =IF($C8="","",IFERROR($D8*VLOOKUP($C8,Foods!$A:$E,5,FALSE),"Add to Foods")) -> 5 | I8: =IF($C8="","",IF(COUNTIF(Foods!$A:$A,$C8)>0,"Yes","No - add nickname")) -> Yes
A9: 46196 | B9: Dessert | C9: Apple Pie Slice | D9: 1 | E9: =IF($C9="","",IFERROR($D9*VLOOKUP($C9,Foods!$A:$E,3,FALSE),"Add to Foods")) -> 450 | F9: =IF($C9="","",IFERROR($D9*VLOOKUP($C9,Foods!$A:$E,4,FALSE),"Add to Foods")) -> 3 | G9: =IF($C9="","",IFERROR($D9*VLOOKUP($C9,Foods!$A:$E,5,FALSE),"Add to Foods")) -> 2 | I9: =IF($C9="","",IF(COUNTIF(Foods!$A:$A,$C9)>0,"Yes","No - add nickname")) -> Yes
A10: 46197 | B10: Breakfast | C10: Peach | D10: 1 | E10: =IF($C10="","",IFERROR($D10*VLOOKUP($C10,Foods!$A:$E,3,FALSE),"Add to Foods")) -> 60 | F10: =IF($C10="","",IFERROR($D10*VLOOKUP($C10,Foods!$A:$E,4,FALSE),"Add to Foods")) -> 1 | G10: =IF($C10="","",IFERROR($D10*VLOOKUP($C10,Foods!$A:$E,5,FALSE),"Add to Foods")) -> 9 | I10: =IF($C10="","",IF(COUNTIF(Foods!$A:$A,$C10)>0,"Yes","No - add nickname")) -> Yes
A11: 46197 | B11: Breakfast | C11: Blueberry Protein Shake | D11: 1 | E11: =IF($C11="","",IFERROR($D11*VLOOKUP($C11,Foods!$A:$E,3,FALSE),"Add to Foods")) -> 450 | F11: =IF($C11="","",IFERROR($D11*VLOOKUP($C11,Foods!$A:$E,4,FALSE),"Add to Foods")) -> 35 | G11: =IF($C11="","",IFERROR($D11*VLOOKUP($C11,Foods!$A:$E,5,FALSE),"Add to Foods")) -> 9 | I11: =IF($C11="","",IF(COUNTIF(Foods!$A:$A,$C11)>0,"Yes","No - add nickname")) -> Yes
A12: 46197 | B12: Lunch | C12: Turkey sandwich | D12: 1 | E12: =IF($C12="","",IFERROR($D12*VLOOKUP($C12,Foods!$A:$E,3,FALSE),"Add to Foods")) -> 460 | F12: =IF($C12="","",IFERROR($D12*VLOOKUP($C12,Foods!$A:$E,4,FALSE),"Add to Foods")) -> 29 | G12: =IF($C12="","",IFERROR($D12*VLOOKUP($C12,Foods!$A:$E,5,FALSE),"Add to Foods")) -> 7 | I12: =IF($C12="","",IF(COUNTIF(Foods!$A:$A,$C12)>0,"Yes","No - add nickname")) -> Yes
A13: 46197 | B13: Lunch | C13: Watermelon | D13: 1 | E13: =IF($C13="","",IFERROR($D13*VLOOKUP($C13,Foods!$A:$E,3,FALSE),"Add to Foods")) -> 50 | F13: =IF($C13="","",IFERROR($D13*VLOOKUP($C13,Foods!$A:$E,4,FALSE),"Add to Foods")) -> 1 | G13: =IF($C13="","",IFERROR($D13*VLOOKUP($C13,Foods!$A:$E,5,FALSE),"Add to Foods")) -> 9 | I13: =IF($C13="","",IF(COUNTIF(Foods!$A:$A,$C13)>0,"Yes","No - add nickname")) -> Yes
A14: 46197 | B14: Snack | C14: Olipop | D14: 1 | E14: =IF($C14="","",IFERROR($D14*VLOOKUP($C14,Foods!$A:$E,3,FALSE),"Add to Foods")) -> 40 | F14: =IF($C14="","",IFERROR($D14*VLOOKUP($C14,Foods!$A:$E,4,FALSE),"Add to Foods")) -> 0 | G14: =IF($C14="","",IFERROR($D14*VLOOKUP($C14,Foods!$A:$E,5,FALSE),"Add to Foods")) -> 7 | I14: =IF($C14="","",IF(COUNTIF(Foods!$A:$A,$C14)>0,"Yes","No - add nickname")) -> Yes
A15: 46197 | B15: Dinner | C15: Roasted chicken | D15: 1.5 | E15: =IF($C15="","",IFERROR($D15*VLOOKUP($C15,Foods!$A:$E,3,FALSE),"Add to Foods")) -> 285 | F15: =IF($C15="","",IFERROR($D15*VLOOKUP($C15,Foods!$A:$E,4,FALSE),"Add to Foods")) -> 52.5 | G15: =IF($C15="","",IFERROR($D15*VLOOKUP($C15,Foods!$A:$E,5,FALSE),"Add to Foods")) -> 15 | I15: =IF($C15="","",IF(COUNTIF(Foods!$A:$A,$C15)>0,"Yes","No - add nickname")) -> Yes
A16: 46197 | B16: Dinner | C16: Fingerling potatoes | D16: 2 | E16: =IF($C16="","",IFERROR($D16*VLOOKUP($C16,Foods!$A:$E,3,FALSE),"Add to Foods")) -> 360 | F16: =IF($C16="","",IFERROR($D16*VLOOKUP($C16,Foods!$A:$E,4,FALSE),"Add to Foods")) -> 8 | G16: =IF($C16="","",IFERROR($D16*VLOOKUP($C16,Foods!$A:$E,5,FALSE),"Add to Foods")) -> 16 | I16: =IF($C16="","",IF(COUNTIF(Foods!$A:$A,$C16)>0,"Yes","No - add nickname")) -> Yes
A17: 46197 | B17: Dinner | C17: Broccoli | D17: 1 | E17: =IF($C17="","",IFERROR($D17*VLOOKUP($C17,Foods!$A:$E,3,FALSE),"Add to Foods")) -> 55 | F17: =IF($C17="","",IFERROR($D17*VLOOKUP($C17,Foods!$A:$E,4,FALSE),"Add to Foods")) -> 4 | G17: =IF($C17="","",IFERROR($D17*VLOOKUP($C17,Foods!$A:$E,5,FALSE),"Add to Foods")) -> 10 | I17: =IF($C17="","",IF(COUNTIF(Foods!$A:$A,$C17)>0,"Yes","No - add nickname")) -> Yes
A18: 46197 | B18: Dinner | C18: Plain Whole-Milk Greek Yogurt | D18: 1 | E18: =IF($C18="","",IFERROR($D18*VLOOKUP($C18,Foods!$A:$E,3,FALSE),"Add to Foods")) -> 190 | F18: =IF($C18="","",IFERROR($D18*VLOOKUP($C18,Foods!$A:$E,4,FALSE),"Add to Foods")) -> 18 | G18: =IF($C18="","",IFERROR($D18*VLOOKUP($C18,Foods!$A:$E,5,FALSE),"Add to Foods")) -> 9 | I18: =IF($C18="","",IF(COUNTIF(Foods!$A:$A,$C18)>0,"Yes","No - add nickname")) -> Yes
... A56: 46201 | B56: Lunch | C56: Leafy greens salad w/cheese | D56: 1 | E56: =IF($C56="","",IFERROR($D56*VLOOKUP($C56,Foods!$A:$E,3,FALSE),"Add to Foods")) -> 60 | F56: =IF($C56="","",IFERROR($D56*VLOOKUP($C56,Foods!$A:$E,4,FALSE),"Add to Foods")) -> 1 | G56: =IF($C56="","",IFERROR($D56*VLOOKUP($C56,Foods!$A:$E,5,FALSE),"Add to Foods")) -> 9 | I56: =IF($C56="","",IF(COUNTIF(Foods!$A:$A,$C56)>0,"Yes","No - add nickname")) -> Yes
E57: =IF($C57="","",IFERROR($D57*VLOOKUP($C57,Foods!$A:$E,3,FALSE),"Add to Foods")) | F57: =IF($C57="","",IFERROR($D57*VLOOKUP($C57,Foods!$A:$E,4,FALSE),"Add to Foods")) | G57: =IF($C57="","",IFERROR($D57*VLOOKUP($C57,Foods!$A:$E,5,FALSE),"Add to Foods")) | I57: =IF($C57="","",IF(COUNTIF(Foods!$A:$A,$C57)>0,"Yes","No - add nickname"))
E58: =IF($C58="","",IFERROR($D58*VLOOKUP($C58,Foods!$A:$E,3,FALSE),"Add to Foods")) | F58: =IF($C58="","",IFERROR($D58*VLOOKUP($C58,Foods!$A:$E,4,FALSE),"Add to Foods")) | G58: =IF($C58="","",IFERROR($D58*VLOOKUP($C58,Foods!$A:$E,5,FALSE),"Add to Foods")) | I58: =IF($C58="","",IF(COUNTIF(Foods!$A:$A,$C58)>0,"Yes","No - add nickname"))
E59: =IF($C59="","",IFERROR($D59*VLOOKUP($C59,Foods!$A:$E,3,FALSE),"Add to Foods")) | F59: =IF($C59="","",IFERROR($D59*VLOOKUP($C59,Foods!$A:$E,4,FALSE),"Add to Foods")) | G59: =IF($C59="","",IFERROR($D59*VLOOKUP($C59,Foods!$A:$E,5,FALSE),"Add to Foods")) | I59: =IF($C59="","",IF(COUNTIF(Foods!$A:$A,$C59)>0,"Yes","No - add nickname"))
E60: =IF($C60="","",IFERROR($D60*VLOOKUP($C60,Foods!$A:$E,3,FALSE),"Add to Foods")) | F60: =IF($C60="","",IFERROR($D60*VLOOKUP($C60,Foods!$A:$E,4,FALSE),"Add to Foods")) | G60: =IF($C60="","",IFERROR($D60*VLOOKUP($C60,Foods!$A:$E,5,FALSE),"Add to Foods")) | I60: =IF($C60="","",IF(COUNTIF(Foods!$A:$A,$C60)>0,"Yes","No - add nickname"))
E61: =IF($C61="","",IFERROR($D61*VLOOKUP($C61,Foods!$A:$E,3,FALSE),"Add to Foods")) | F61: =IF($C61="","",IFERROR($D61*VLOOKUP($C61,Foods!$A:$E,4,FALSE),"Add to Foods")) | G61: =IF($C61="","",IFERROR($D61*VLOOKUP($C61,Foods!$A:$E,5,FALSE),"Add to Foods")) | I61: =IF($C61="","",IF(COUNTIF(Foods!$A:$A,$C61)>0,"Yes","No - add nickname"))
E62: =IF($C62="","",IFERROR($D62*VLOOKUP($C62,Foods!$A:$E,3,FALSE),"Add to Foods")) | F62: =IF($C62="","",IFERROR($D62*VLOOKUP($C62,Foods!$A:$E,4,FALSE),"Add to Foods")) | G62: =IF($C62="","",IFERROR($D62*VLOOKUP($C62,Foods!$A:$E,5,FALSE),"Add to Foods")) | I62: =IF($C62="","",IF(COUNTIF(Foods!$A:$A,$C62)>0,"Yes","No - add nickname"))
E63: =IF($C63="","",IFERROR($D63*VLOOKUP($C63,Foods!$A:$E,3,FALSE),"Add to Foods")) | F63: =IF($C63="","",IFERROR($D63*VLOOKUP($C63,Foods!$A:$E,4,FALSE),"Add to Foods")) | G63: =IF($C63="","",IFERROR($D63*VLOOKUP($C63,Foods!$A:$E,5,FALSE),"Add to Foods")) | I63: =IF($C63="","",IF(COUNTIF(Foods!$A:$A,$C63)>0,"Yes","No - add nickname"))
E64: =IF($C64="","",IFERROR($D64*VLOOKUP($C64,Foods!$A:$E,3,FALSE),"Add to Foods")) | F64: =IF($C64="","",IFERROR($D64*VLOOKUP($C64,Foods!$A:$E,4,FALSE),"Add to Foods")) | G64: =IF($C64="","",IFERROR($D64*VLOOKUP($C64,Foods!$A:$E,5,FALSE),"Add to Foods")) | I64: =IF($C64="","",IF(COUNTIF(Foods!$A:$A,$C64)>0,"Yes","No - add nickname"))
E65: =IF($C65="","",IFERROR($D65*VLOOKUP($C65,Foods!$A:$E,3,FALSE),"Add to Foods")) | F65: =IF($C65="","",IFERROR($D65*VLOOKUP($C65,Foods!$A:$E,4,FALSE),"Add to Foods")) | G65: =IF($C65="","",IFERROR($D65*VLOOKUP($C65,Foods!$A:$E,5,FALSE),"Add to Foods")) | I65: =IF($C65="","",IF(COUNTIF(Foods!$A:$A,$C65)>0,"Yes","No - add nickname"))
E66: =IF($C66="","",IFERROR($D66*VLOOKUP($C66,Foods!$A:$E,3,FALSE),"Add to Foods")) | F66: =IF($C66="","",IFERROR($D66*VLOOKUP($C66,Foods!$A:$E,4,FALSE),"Add to Foods")) | G66: =IF($C66="","",IFERROR($D66*VLOOKUP($C66,Foods!$A:$E,5,FALSE),"Add to Foods")) | I66: =IF($C66="","",IF(COUNTIF(Foods!$A:$A,$C66)>0,"Yes","No - add nickname"))
E67: =IF($C67="","",IFERROR($D67*VLOOKUP($C67,Foods!$A:$E,3,FALSE),"Add to Foods")) | F67: =IF($C67="","",IFERROR($D67*VLOOKUP($C67,Foods!$A:$E,4,FALSE),"Add to Foods")) | G67: =IF($C67="","",IFERROR($D67*VLOOKUP($C67,Foods!$A:$E,5,FALSE),"Add to Foods")) | I67: =IF($C67="","",IF(COUNTIF(Foods!$A:$A,$C67)>0,"Yes","No - add nickname"))
E68: =IF($C68="","",IFERROR($D68*VLOOKUP($C68,Foods!$A:$E,3,FALSE),"Add to Foods")) | F68: =IF($C68="","",IFERROR($D68*VLOOKUP($C68,Foods!$A:$E,4,FALSE),"Add to Foods")) | G68: =IF($C68="","",IFERROR($D68*VLOOKUP($C68,Foods!$A:$E,5,FALSE),"Add to Foods")) | I68: =IF($C68="","",IF(COUNTIF(Foods!$A:$A,$C68)>0,"Yes","No - add nickname"))
... E506: =IF($C506="","",IFERROR($D506*VLOOKUP($C506,Foods!$A:$E,3,FALSE),"Add to Foods")) | F506: =IF($C506="","",IFERROR($D506*VLOOKUP($C506,Foods!$A:$E,4,FALSE),"Add to Foods")) | G506: =IF($C506="","",IFERROR($D506*VLOOKUP($C506,Foods!$A:$E,5,FALSE),"Add to Foods")) | I506: =IF($C506="","",IF(COUNTIF(Foods!$A:$A,$C506)>0,"Yes","No - add nickname"))

Sheet Foods
A1: Food Name / Nickname | B1: Serving Description | C1: Calories | D1: Protein (g) | E1: Nutrition Score (1-10) | F1: Satiety Score | G1: Notes
A2: Blueberry Protein Shake | B2: 1 shake: whole milk + protein powder + 1 cup blueberries | C2: 450 | D2: 35 | E2: 9 | G2: Adjust if you change milk amount/type.
A3: PB Sandwich | B3: 1 sandwich on sourdough | C3: 395 | D3: 18 | E3: 7 | G3: Peanut butter amount drives calories.
A4: PB Banana Sandwich | B4: 1 sandwich on sourdough | C4: 500 | D4: 18 | E4: 7 | G4: Peanut butter amount drives calories.
A5: Mixed Nuts & Raisins (1 cup) | B5: 1 cup | C5: 650 | D5: 18 | E5: 6 | G5: Calorie dense; try 1/2 cup when cutting.
A6: Udon Bowl | B6: 1 bowl | C6: 700 | D6: 20 | E6: 5 | G6: Estimate; refine for restaurant/home version.
A7: Apple Pie Slice | B7: 1 large slice | C7: 450 | D7: 3 | E7: 2 | G7: Treat food.
A8: Cereal with Whole Milk | B8: 1 small bowl | C8: 400 | D8: 12 | E8: 6 | G8: Estimate depends on cereal and milk volume.
A9: Black Coffee / Tea / Sparkling Water | B9: 1 drink | C9: 0 | D9: 0 | E9: 10 | G9: Calorie-free beverages.
A10: Banana | B10: 1 medium | C10: 105 | D10: 1 | E10: 8
A11: Apple | B11: 1 medium | C11: 95 | D11: 0 | E11: 8
A12: Peach | B12: 1 medium | C12: 60 | D12: 1 | E12: 9 | F12: 7
A13: Greek Yogurt + Berries | B13: 1 bowl | C13: 250 | D13: 20 | E13: 9 | G13: Good default snack.
A14: Eggs + Toast | B14: 2 eggs + 1 toast | C14: 320 | D14: 18 | E14: 8
A15: Chicken Salad | B15: 1 large salad | C15: 450 | D15: 35 | E15: 9
A16: Rice Bowl with Protein | B16: 1 bowl | C16: 650 | D16: 35 | E16: 7
A17: Pizza Slice | B17: 1 slice | C17: 300 | D17: 12 | E17: 4
A18: Protein Bar | B18: 1 bar | C18: 220 | D18: 20 | E18: 6 | G18: Check label.
A19: Leafy greens salad w/cheese | B19: 1 bowl | C19: 60 | D19: 1 | E19: 9 | F19: 7
A20: Leafy greens salad w/tomatoes | B20: 1 bowl | C20: 40 | D20: 2 | E20: 10 | F20: 5
A21: Corn chips and salsa | B21: 1 small bowl | C21: 180 | D21: 3 | E21: 4 | F21: 3
A22: Plain Nonfat Greek Yogurt | B22: 1 cup | C22: 130 | D22: 23 | E22: 9 | F22: 8
A23: Plain Low-Fat Greek Yogurt | B23: 1 cup | C23: 150 | D23: 20 | E23: 9 | F23: 8
A24: Plain Whole-Milk Greek Yogurt | B24: 1 cup | C24: 190 | D24: 18 | E24: 9 | F24: 8
A25: Plain Regular Yogurt (whole milk) | B25: 1 cup | C25: 150 | D25: 8 | E25: 9 | F25: 8
A26: Turkey sandwich | B26: 1 sandwich | C26: 460 | D26: 29 | E26: 7 | G26: Assumes whole wheat bread, about 2 oz turkey, and 2 slices cheddar or Swiss.
A27: Watermelon | B27: 1 cup diced | C27: 50 | D27: 1 | E27: 9 | G27: Very hydrating, low calorie, good source of vitamins A and C.
A28: Olipop | B28: 1 can | C28: 40 | D28: 0 | E28: 7 | G28: Prebiotics
A29: Roasted chicken | B29: 4 oz cooked, skinless | C29: 190 | D29: 35 | E29: 10 | G29: Excellent lean protein, rich in B vitamins.
A30: Broccoli | B30: 1 cup cooked | C30: 55 | D30: 4 | E30: 10 | G30: High in fiber, vitamin C, vitamin K, and folate.
A31: Fingerling potatoes | B31: 1 cup roasted (about 6 oz) | C31: 180 | D31: 4 | E31: 8 | G31: Good source of potassium and vitamin C; score assumes moderate oil when roasted.
A32: Tamale, black bean and yam | B32: 1 tamale | C32: 400 | D32: 12 | E32: 9
A33: Tamale, chicken | B33: 1 tamale | C33: 400 | D33: 20 | E33: 8.8
A34: Tamale, beef and cheese | B34: 1 tamale | C34: 460 | D34: 21 | E34: 7.8
A35: IPA beer | B35: 1 pint (16 oz) | C35: 250 | D35: 2 | E35: 2
A36: Lager beer | B36: 1 pint (16 oz) | C36: 190 | D36: 2 | E36: 2
A37: Red ale | B37: 1 pint (16 oz) | C37: 210 | D37: 2 | E37: 2
A38: Stout | B38: 1 pint (16 oz) | C38: 220 | D38: 3 | E38: 2
A39: Mango lassi | B39: 12 oz | C39: 320 | D39: 10 | E39: 6
A40: Pepperoni pizza | B40: 1 slice (large) | C40: 320 | D40: 14 | E40: 4
...

Sheet Daily Summary
A1: Date | B1: Calories | C1: Protein (g) | D1: Avg Nutrition Score | E1: Items Logged | F1: Weight | G1: 7-Day Avg Calories | H1: 7-Day Avg Weight
A2: ='Meal Log'!$A$2+0 -> 46196 | B2: =IF($A2="","",SUMIFS('Meal Log'!$E:$E,'Meal Log'!$A:$A,$A2)) -> 3390 | C2: =IF($A2="","",SUMIFS('Meal Log'!$F:$F,'Meal Log'!$A:$A,$A2)) -> 110 | D2: =IF($E2=0,"",ROUND(SUMIFS('Meal Log'!$G:$G,'Meal Log'!$A:$A,$A2)/$E2,1)) -> 6 | E2: =COUNTIF('Meal Log'!$A:$A,$A2) -> 8 | F2: 186.4 | G2: =IFERROR(__xludf.DUMMYFUNCTION("IFERROR(ROUND(AVERAGE(FILTER($B$2:$B2,$A$2:$A2>=$A2-6,$B$2:$B2>0)),0),"""")"),3390.0) -> 3390 | H2: =IFERROR(__xludf.DUMMYFUNCTION("IFERROR(ROUND(AVERAGE(FILTER($F$2:$F2,$A$2:$A2>=$A2-6,$F$2:$F2>0)),1),"""")"),186.4) -> 186.4
A3: ='Meal Log'!$A$2+1 -> 46197 | B3: =IF($A3="","",SUMIFS('Meal Log'!$E:$E,'Meal Log'!$A:$A,$A3)) -> 2055 | C3: =IF($A3="","",SUMIFS('Meal Log'!$F:$F,'Meal Log'!$A:$A,$A3)) -> 149.5 | D3: =IF($E3=0,"",ROUND(SUMIFS('Meal Log'!$G:$G,'Meal Log'!$A:$A,$A3)/$E3,1)) -> 9.9 | E3: =COUNTIF('Meal Log'!$A:$A,$A3) -> 10 | F3: 185.2 | G3: =IFERROR(__xludf.DUMMYFUNCTION("IFERROR(ROUND(AVERAGE(FILTER($B$2:$B3,$A$2:$A3>=$A3-6,$B$2:$B3>0)),0),"""")"),2723.0) -> 2723 | H3: =IFERROR(__xludf.DUMMYFUNCTION("IFERROR(ROUND(AVERAGE(FILTER($F$2:$F3,$A$2:$A3>=$A3-6,$F$2:$F3>0)),1),"""")"),185.8) -> 185.8
A4: ='Meal Log'!$A$2+2 -> 46198 | B4: =IF($A4="","",SUMIFS('Meal Log'!$E:$E,'Meal Log'!$A:$A,$A4)) -> 2220 | C4: =IF($A4="","",SUMIFS('Meal Log'!$F:$F,'Meal Log'!$A:$A,$A4)) -> 109 | D4: =IF($E4=0,"",ROUND(SUMIFS('Meal Log'!$G:$G,'Meal Log'!$A:$A,$A4)/$E4,1)) -> 9.8 | E4: =COUNTIF('Meal Log'!$A:$A,$A4) -> 10 | F4: =IFERROR(VLOOKUP($A4,'Weight Log'!$A:$B,2,FALSE),"") -> 184 | G4: =IFERROR(__xludf.DUMMYFUNCTION("IFERROR(ROUND(AVERAGE(FILTER($B$2:$B4,$A$2:$A4>=$A4-6,$B$2:$B4>0)),0),"""")"),2555.0) -> 2555 | H4: =IFERROR(__xludf.DUMMYFUNCTION("IFERROR(ROUND(AVERAGE(FILTER($F$2:$F4,$A$2:$A4>=$A4-6,$F$2:$F4>0)),1),"""")"),185.2) -> 185.2
A5: ='Meal Log'!$A$2+3 -> 46199 | B5: =IF($A5="","",SUMIFS('Meal Log'!$E:$E,'Meal Log'!$A:$A,$A5)) -> 2285 | C5: =IF($A5="","",SUMIFS('Meal Log'!$F:$F,'Meal Log'!$A:$A,$A5)) -> 127.5 | D5: =IF($E5=0,"",ROUND(SUMIFS('Meal Log'!$G:$G,'Meal Log'!$A:$A,$A5)/$E5,1)) -> 9 | E5: =COUNTIF('Meal Log'!$A:$A,$A5) -> 11 | F5: =IFERROR(VLOOKUP($A5,'Weight Log'!$A:$B,2,FALSE),"") | G5: =IFERROR(__xludf.DUMMYFUNCTION("IFERROR(ROUND(AVERAGE(FILTER($B$2:$B5,$A$2:$A5>=$A5-6,$B$2:$B5>0)),0),"""")"),2488.0) -> 2488 | H5: =IFERROR(__xludf.DUMMYFUNCTION("IFERROR(ROUND(AVERAGE(FILTER($F$2:$F5,$A$2:$A5>=$A5-6,$F$2:$F5>0)),1),"""")"),185.2) -> 185.2
A6: ='Meal Log'!$A$2+4 -> 46200 | B6: =IF($A6="","",SUMIFS('Meal Log'!$E:$E,'Meal Log'!$A:$A,$A6)) -> 2030 | C6: =IF($A6="","",SUMIFS('Meal Log'!$F:$F,'Meal Log'!$A:$A,$A6)) -> 124 | D6: =IF($E6=0,"",ROUND(SUMIFS('Meal Log'!$G:$G,'Meal Log'!$A:$A,$A6)/$E6,1)) -> 9.4 | E6: =COUNTIF('Meal Log'!$A:$A,$A6) -> 12 | F6: =IFERROR(VLOOKUP($A6,'Weight Log'!$A:$B,2,FALSE),"") -> 181.8 | G6: =IFERROR(__xludf.DUMMYFUNCTION("IFERROR(ROUND(AVERAGE(FILTER($B$2:$B6,$A$2:$A6>=$A6-6,$B$2:$B6>0)),0),"""")"),2396.0) -> 2396 | H6: =IFERROR(__xludf.DUMMYFUNCTION("IFERROR(ROUND(AVERAGE(FILTER($F$2:$F6,$A$2:$A6>=$A6-6,$F$2:$F6>0)),1),"""")"),184.4) -> 184.4
A7: ='Meal Log'!$A$2+5 -> 46201 | B7: =IF($A7="","",SUMIFS('Meal Log'!$E:$E,'Meal Log'!$A:$A,$A7)) -> 1015 | C7: =IF($A7="","",SUMIFS('Meal Log'!$F:$F,'Meal Log'!$A:$A,$A7)) -> 57 | D7: =IF($E7=0,"",ROUND(SUMIFS('Meal Log'!$G:$G,'Meal Log'!$A:$A,$A7)/$E7,1)) -> 8.7 | E7: =COUNTIF('Meal Log'!$A:$A,$A7) -> 4 | F7: =IFERROR(VLOOKUP($A7,'Weight Log'!$A:$B,2,FALSE),"") | G7: =IFERROR(__xludf.DUMMYFUNCTION("IFERROR(ROUND(AVERAGE(FILTER($B$2:$B7,$A$2:$A7>=$A7-6,$B$2:$B7>0)),0),"""")"),2166.0) -> 2166 | H7: =IFERROR(__xludf.DUMMYFUNCTION("IFERROR(ROUND(AVERAGE(FILTER($F$2:$F7,$A$2:$A7>=$A7-6,$F$2:$F7>0)),1),"""")"),184.4) -> 184.4
A8: ='Meal Log'!$A$2+6 -> 46202 | B8: =IF($A8="","",SUMIFS('Meal Log'!$E:$E,'Meal Log'!$A:$A,$A8)) -> 0 | C8: =IF($A8="","",SUMIFS('Meal Log'!$F:$F,'Meal Log'!$A:$A,$A8)) -> 0 | D8: =IF($E8=0,"",ROUND(SUMIFS('Meal Log'!$G:$G,'Meal Log'!$A:$A,$A8)/$E8,1)) | E8: =COUNTIF('Meal Log'!$A:$A,$A8) -> 0 | F8: =IFERROR(VLOOKUP($A8,'Weight Log'!$A:$B,2,FALSE),"") | G8: =IFERROR(__xludf.DUMMYFUNCTION("IFERROR(ROUND(AVERAGE(FILTER($B$2:$B8,$A$2:$A8>=$A8-6,$B$2:$B8>0)),0),"""")"),2166.0) -> 2166 | H8: =IFERROR(__xludf.DUMMYFUNCTION("IFERROR(ROUND(AVERAGE(FILTER($F$2:$F8,$A$2:$A8>=$A8-6,$F$2:$F8>0)),1),"""")"),184.4) -> 184.4
A9: ='Meal Log'!$A$2+7 -> 46203 | B9: =IF($A9="","",SUMIFS('Meal Log'!$E:$E,'Meal Log'!$A:$A,$A9)) -> 0 | C9: =IF($A9="","",SUMIFS('Meal Log'!$F:$F,'Meal Log'!$A:$A,$A9)) -> 0 | D9: =IF($E9=0,"",ROUND(SUMIFS('Meal Log'!$G:$G,'Meal Log'!$A:$A,$A9)/$E9,1)) | E9: =COUNTIF('Meal Log'!$A:$A,$A9) -> 0 | F9: =IFERROR(VLOOKUP($A9,'Weight Log'!$A:$B,2,FALSE),"") | G9: =IFERROR(__xludf.DUMMYFUNCTION("IFERROR(ROUND(AVERAGE(FILTER($B$2:$B9,$A$2:$A9>=$A9-6,$B$2:$B9>0)),0),"""")"),1921.0) -> 1921 | H9: =IFERROR(__xludf.DUMMYFUNCTION("IFERROR(ROUND(AVERAGE(FILTER($F$2:$F9,$A$2:$A9>=$A9-6,$F$2:$F9>0)),1),"""")"),183.7) -> 183.7
A10: ='Meal Log'!$A$2+8 -> 46204 | B10: =IF($A10="","",SUMIFS('Meal Log'!$E:$E,'Meal Log'!$A:$A,$A10)) -> 0 | C10: =IF($A10="","",SUMIFS('Meal Log'!$F:$F,'Meal Log'!$A:$A,$A10)) -> 0 | D10: =IF($E10=0,"",ROUND(SUMIFS('Meal Log'!$G:$G,'Meal Log'!$A:$A,$A10)/$E10,1)) | E10: =COUNTIF('Meal Log'!$A:$A,$A10) -> 0 | F10: =IFERROR(VLOOKUP($A10,'Weight Log'!$A:$B,2,FALSE),"") | G10: =IFERROR(__xludf.DUMMYFUNCTION("IFERROR(ROUND(AVERAGE(FILTER($B$2:$B10,$A$2:$A10>=$A10-6,$B$2:$B10>0)),0),"""")"),1888.0) -> 1888 | H10: =IFERROR(__xludf.DUMMYFUNCTION("IFERROR(ROUND(AVERAGE(FILTER($F$2:$F10,$A$2:$A10>=$A10-6,$F$2:$F10>0)),1),"""")"),182.9) -> 182.9
A11: ='Meal Log'!$A$2+9 -> 46205 | B11: =IF($A11="","",SUMIFS('Meal Log'!$E:$E,'Meal Log'!$A:$A,$A11)) -> 0 | C11: =IF($A11="","",SUMIFS('Meal Log'!$F:$F,'Meal Log'!$A:$A,$A11)) -> 0 | D11: =IF($E11=0,"",ROUND(SUMIFS('Meal Log'!$G:$G,'Meal Log'!$A:$A,$A11)/$E11,1)) | E11: =COUNTIF('Meal Log'!$A:$A,$A11) -> 0 | F11: =IFERROR(VLOOKUP($A11,'Weight Log'!$A:$B,2,FALSE),"") | G11: =IFERROR(__xludf.DUMMYFUNCTION("IFERROR(ROUND(AVERAGE(FILTER($B$2:$B11,$A$2:$A11>=$A11-6,$B$2:$B11>0)),0),"""")"),1777.0) -> 1777 | H11: =IFERROR(__xludf.DUMMYFUNCTION("IFERROR(ROUND(AVERAGE(FILTER($F$2:$F11,$A$2:$A11>=$A11-6,$F$2:$F11>0)),1),"""")"),181.8) -> 181.8
A12: ='Meal Log'!$A$2+10 -> 46206 | B12: =IF($A12="","",SUMIFS('Meal Log'!$E:$E,'Meal Log'!$A:$A,$A12)) -> 0 | C12: =IF($A12="","",SUMIFS('Meal Log'!$F:$F,'Meal Log'!$A:$A,$A12)) -> 0 | D12: =IF($E12=0,"",ROUND(SUMIFS('Meal Log'!$G:$G,'Meal Log'!$A:$A,$A12)/$E12,1)) | E12: =COUNTIF('Meal Log'!$A:$A,$A12) -> 0 | F12: =IFERROR(VLOOKUP($A12,'Weight Log'!$A:$B,2,FALSE),"") | G12: =IFERROR(__xludf.DUMMYFUNCTION("IFERROR(ROUND(AVERAGE(FILTER($B$2:$B12,$A$2:$A12>=$A12-6,$B$2:$B12>0)),0),"""")"),1523.0) -> 1523 | H12: =IFERROR(__xludf.DUMMYFUNCTION("IFERROR(ROUND(AVERAGE(FILTER($F$2:$F12,$A$2:$A12>=$A12-6,$F$2:$F12>0)),1),"""")"),181.8) -> 181.8
A13: ='Meal Log'!$A$2+11 -> 46207 | B13: =IF($A13="","",SUMIFS('Meal Log'!$E:$E,'Meal Log'!$A:$A,$A13)) -> 0 | C13: =IF($A13="","",SUMIFS('Meal Log'!$F:$F,'Meal Log'!$A:$A,$A13)) -> 0 | D13: =IF($E13=0,"",ROUND(SUMIFS('Meal Log'!$G:$G,'Meal Log'!$A:$A,$A13)/$E13,1)) | E13: =COUNTIF('Meal Log'!$A:$A,$A13) -> 0 | F13: =IFERROR(VLOOKUP($A13,'Weight Log'!$A:$B,2,FALSE),"") | G13: =IFERROR(__xludf.DUMMYFUNCTION("IFERROR(ROUND(AVERAGE(FILTER($B$2:$B13,$A$2:$A13>=$A13-6,$B$2:$B13>0)),0),"""")"),1015.0) -> 1015 | H13: =IFERROR(__xludf.DUMMYFUNCTION("IFERROR(ROUND(AVERAGE(FILTER($F$2:$F13,$A$2:$A13>=$A13-6,$F$2:$F13>0)),1),"""")"),"")
A14: ='Meal Log'!$A$2+12 -> 46208 | B14: =IF($A14="","",SUMIFS('Meal Log'!$E:$E,'Meal Log'!$A:$A,$A14)) -> 0 | C14: =IF($A14="","",SUMIFS('Meal Log'!$F:$F,'Meal Log'!$A:$A,$A14)) -> 0 | D14: =IF($E14=0,"",ROUND(SUMIFS('Meal Log'!$G:$G,'Meal Log'!$A:$A,$A14)/$E14,1)) | E14: =COUNTIF('Meal Log'!$A:$A,$A14) -> 0 | F14: =IFERROR(VLOOKUP($A14,'Weight Log'!$A:$B,2,FALSE),"") | G14: =IFERROR(__xludf.DUMMYFUNCTION("IFERROR(ROUND(AVERAGE(FILTER($B$2:$B14,$A$2:$A14>=$A14-6,$B$2:$B14>0)),0),"""")"),"") | H14: =IFERROR(__xludf.DUMMYFUNCTION("IFERROR(ROUND(AVERAGE(FILTER($F$2:$F14,$A$2:$A14>=$A14-6,$F$2:$F14>0)),1),"""")"),"")
A15: ='Meal Log'!$A$2+13 -> 46209 | B15: =IF($A15="","",SUMIFS('Meal Log'!$E:$E,'Meal Log'!$A:$A,$A15)) -> 0 | C15: =IF($A15="","",SUMIFS('Meal Log'!$F:$F,'Meal Log'!$A:$A,$A15)) -> 0 | D15: =IF($E15=0,"",ROUND(SUMIFS('Meal Log'!$G:$G,'Meal Log'!$A:$A,$A15)/$E15,1)) | E15: =COUNTIF('Meal Log'!$A:$A,$A15) -> 0 | F15: =IFERROR(VLOOKUP($A15,'Weight Log'!$A:$B,2,FALSE),"") | G15: =IFERROR(__xludf.DUMMYFUNCTION("IFERROR(ROUND(AVERAGE(FILTER($B$2:$B15,$A$2:$A15>=$A15-6,$B$2:$B15>0)),0),"""")"),"") | H15: =IFERROR(__xludf.DUMMYFUNCTION("IFERROR(ROUND(AVERAGE(FILTER($F$2:$F15,$A$2:$A15>=$A15-6,$F$2:$F15>0)),1),"""")"),"")
A16: ='Meal Log'!$A$2+14 -> 46210 | B16: =IF($A16="","",SUMIFS('Meal Log'!$E:$E,'Meal Log'!$A:$A,$A16)) -> 0 | C16: =IF($A16="","",SUMIFS('Meal Log'!$F:$F,'Meal Log'!$A:$A,$A16)) -> 0 | D16: =IF($E16=0,"",ROUND(SUMIFS('Meal Log'!$G:$G,'Meal Log'!$A:$A,$A16)/$E16,1)) | E16: =COUNTIF('Meal Log'!$A:$A,$A16) -> 0 | F16: =IFERROR(VLOOKUP($A16,'Weight Log'!$A:$B,2,FALSE),"") | G16: =IFERROR(__xludf.DUMMYFUNCTION("IFERROR(ROUND(AVERAGE(FILTER($B$2:$B16,$A$2:$A16>=$A16-6,$B$2:$B16>0)),0),"""")"),"") | H16: =IFERROR(__xludf.DUMMYFUNCTION("IFERROR(ROUND(AVERAGE(FILTER($F$2:$F16,$A$2:$A16>=$A16-6,$F$2:$F16>0)),1),"""")"),"")
A17: ='Meal Log'!$A$2+15 -> 46211 | B17: =IF($A17="","",SUMIFS('Meal Log'!$E:$E,'Meal Log'!$A:$A,$A17)) -> 0 | C17: =IF($A17="","",SUMIFS('Meal Log'!$F:$F,'Meal Log'!$A:$A,$A17)) -> 0 | D17: =IF($E17=0,"",ROUND(SUMIFS('Meal Log'!$G:$G,'Meal Log'!$A:$A,$A17)/$E17,1)) | E17: =COUNTIF('Meal Log'!$A:$A,$A17) -> 0 | F17: =IFERROR(VLOOKUP($A17,'Weight Log'!$A:$B,2,FALSE),"") | G17: =IFERROR(__xludf.DUMMYFUNCTION("IFERROR(ROUND(AVERAGE(FILTER($B$2:$B17,$A$2:$A17>=$A17-6,$B$2:$B17>0)),0),"""")"),"") | H17: =IFERROR(__xludf.DUMMYFUNCTION("IFERROR(ROUND(AVERAGE(FILTER($F$2:$F17,$A$2:$A17>=$A17-6,$F$2:$F17>0)),1),"""")"),"")
A18: ='Meal Log'!$A$2+16 -> 46212 | B18: =IF($A18="","",SUMIFS('Meal Log'!$E:$E,'Meal Log'!$A:$A,$A18)) -> 0 | C18: =IF($A18="","",SUMIFS('Meal Log'!$F:$F,'Meal Log'!$A:$A,$A18)) -> 0 | D18: =IF($E18=0,"",ROUND(SUMIFS('Meal Log'!$G:$G,'Meal Log'!$A:$A,$A18)/$E18,1)) | E18: =COUNTIF('Meal Log'!$A:$A,$A18) -> 0 | F18: =IFERROR(VLOOKUP($A18,'Weight Log'!$A:$B,2,FALSE),"") | G18: =IFERROR(__xludf.DUMMYFUNCTION("IFERROR(ROUND(AVERAGE(FILTER($B$2:$B18,$A$2:$A18>=$A18-6,$B$2:$B18>0)),0),"""")"),"") | H18: =IFERROR(__xludf.DUMMYFUNCTION("IFERROR(ROUND(AVERAGE(FILTER($F$2:$F18,$A$2:$A18>=$A18-6,$F$2:$F18>0)),1),"""")"),"")
A19: ='Meal Log'!$A$2+17 -> 46213 | B19: =IF($A19="","",SUMIFS('Meal Log'!$E:$E,'Meal Log'!$A:$A,$A19)) -> 0 | C19: =IF($A19="","",SUMIFS('Meal Log'!$F:$F,'Meal Log'!$A:$A,$A19)) -> 0 | D19: =IF($E19=0,"",ROUND(SUMIFS('Meal Log'!$G:$G,'Meal Log'!$A:$A,$A19)/$E19,1)) | E19: =COUNTIF('Meal Log'!$A:$A,$A19) -> 0 | F19: =IFERROR(VLOOKUP($A19,'Weight Log'!$A:$B,2,FALSE),"") | G19: =IFERROR(__xludf.DUMMYFUNCTION("IFERROR(ROUND(AVERAGE(FILTER($B$2:$B19,$A$2:$A19>=$A19-6,$B$2:$B19>0)),0),"""")"),"") | H19: =IFERROR(__xludf.DUMMYFUNCTION("IFERROR(ROUND(AVERAGE(FILTER($F$2:$F19,$A$2:$A19>=$A19-6,$F$2:$F19>0)),1),"""")"),"")
A20: ='Meal Log'!$A$2+18 -> 46214 | B20: =IF($A20="","",SUMIFS('Meal Log'!$E:$E,'Meal Log'!$A:$A,$A20)) -> 0 | C20: =IF($A20="","",SUMIFS('Meal Log'!$F:$F,'Meal Log'!$A:$A,$A20)) -> 0 | D20: =IF($E20=0,"",ROUND(SUMIFS('Meal Log'!$G:$G,'Meal Log'!$A:$A,$A20)/$E20,1)) | E20: =COUNTIF('Meal Log'!$A:$A,$A20) -> 0 | F20: =IFERROR(VLOOKUP($A20,'Weight Log'!$A:$B,2,FALSE),"") | G20: =IFERROR(__xludf.DUMMYFUNCTION("IFERROR(ROUND(AVERAGE(FILTER($B$2:$B20,$A$2:$A20>=$A20-6,$B$2:$B20>0)),0),"""")"),"") | H20: =IFERROR(__xludf.DUMMYFUNCTION("IFERROR(ROUND(AVERAGE(FILTER($F$2:$F20,$A$2:$A20>=$A20-6,$F$2:$F20>0)),1),"""")"),"")
A21: ='Meal Log'!$A$2+19 -> 46215 | B21: =IF($A21="","",SUMIFS('Meal Log'!$E:$E,'Meal Log'!$A:$A,$A21)) -> 0 | C21: =IF($A21="","",SUMIFS('Meal Log'!$F:$F,'Meal Log'!$A:$A,$A21)) -> 0 | D21: =IF($E21=0,"",ROUND(SUMIFS('Meal Log'!$G:$G,'Meal Log'!$A:$A,$A21)/$E21,1)) | E21: =COUNTIF('Meal Log'!$A:$A,$A21) -> 0 | F21: =IFERROR(VLOOKUP($A21,'Weight Log'!$A:$B,2,FALSE),"") | G21: =IFERROR(__xludf.DUMMYFUNCTION("IFERROR(ROUND(AVERAGE(FILTER($B$2:$B21,$A$2:$A21>=$A21-6,$B$2:$B21>0)),0),"""")"),"") | H21: =IFERROR(__xludf.DUMMYFUNCTION("IFERROR(ROUND(AVERAGE(FILTER($F$2:$F21,$A$2:$A21>=$A21-6,$F$2:$F21>0)),1),"""")"),"")
A22: ='Meal Log'!$A$2+20 -> 46216 | B22: =IF($A22="","",SUMIFS('Meal Log'!$E:$E,'Meal Log'!$A:$A,$A22)) -> 0 | C22: =IF($A22="","",SUMIFS('Meal Log'!$F:$F,'Meal Log'!$A:$A,$A22)) -> 0 | D22: =IF($E22=0,"",ROUND(SUMIFS('Meal Log'!$G:$G,'Meal Log'!$A:$A,$A22)/$E22,1)) | E22: =COUNTIF('Meal Log'!$A:$A,$A22) -> 0 | F22: =IFERROR(VLOOKUP($A22,'Weight Log'!$A:$B,2,FALSE),"") | G22: =IFERROR(__xludf.DUMMYFUNCTION("IFERROR(ROUND(AVERAGE(FILTER($B$2:$B22,$A$2:$A22>=$A22-6,$B$2:$B22>0)),0),"""")"),"") | H22: =IFERROR(__xludf.DUMMYFUNCTION("IFERROR(ROUND(AVERAGE(FILTER($F$2:$F22,$A$2:$A22>=$A22-6,$F$2:$F22>0)),1),"""")"),"")
A23: ='Meal Log'!$A$2+21 -> 46217 | B23: =IF($A23="","",SUMIFS('Meal Log'!$E:$E,'Meal Log'!$A:$A,$A23)) -> 0 | C23: =IF($A23="","",SUMIFS('Meal Log'!$F:$F,'Meal Log'!$A:$A,$A23)) -> 0 | D23: =IF($E23=0,"",ROUND(SUMIFS('Meal Log'!$G:$G,'Meal Log'!$A:$A,$A23)/$E23,1)) | E23: =COUNTIF('Meal Log'!$A:$A,$A23) -> 0 | F23: =IFERROR(VLOOKUP($A23,'Weight Log'!$A:$B,2,FALSE),"") | G23: =IFERROR(__xludf.DUMMYFUNCTION("IFERROR(ROUND(AVERAGE(FILTER($B$2:$B23,$A$2:$A23>=$A23-6,$B$2:$B23>0)),0),"""")"),"") | H23: =IFERROR(__xludf.DUMMYFUNCTION("IFERROR(ROUND(AVERAGE(FILTER($F$2:$F23,$A$2:$A23>=$A23-6,$F$2:$F23>0)),1),"""")"),"")
A24: ='Meal Log'!$A$2+22 -> 46218 | B24: =IF($A24="","",SUMIFS('Meal Log'!$E:$E,'Meal Log'!$A:$A,$A24)) -> 0 | C24: =IF($A24="","",SUMIFS('Meal Log'!$F:$F,'Meal Log'!$A:$A,$A24)) -> 0 | D24: =IF($E24=0,"",ROUND(SUMIFS('Meal Log'!$G:$G,'Meal Log'!$A:$A,$A24)/$E24,1)) | E24: =COUNTIF('Meal Log'!$A:$A,$A24) -> 0 | F24: =IFERROR(VLOOKUP($A24,'Weight Log'!$A:$B,2,FALSE),"") | G24: =IFERROR(__xludf.DUMMYFUNCTION("IFERROR(ROUND(AVERAGE(FILTER($B$2:$B24,$A$2:$A24>=$A24-6,$B$2:$B24>0)),0),"""")"),"") | H24: =IFERROR(__xludf.DUMMYFUNCTION("IFERROR(ROUND(AVERAGE(FILTER($F$2:$F24,$A$2:$A24>=$A24-6,$F$2:$F24>0)),1),"""")"),"")
A25: ='Meal Log'!$A$2+23 -> 46219 | B25: =IF($A25="","",SUMIFS('Meal Log'!$E:$E,'Meal Log'!$A:$A,$A25)) -> 0 | C25: =IF($A25="","",SUMIFS('Meal Log'!$F:$F,'Meal Log'!$A:$A,$A25)) -> 0 | D25: =IF($E25=0,"",ROUND(SUMIFS('Meal Log'!$G:$G,'Meal Log'!$A:$A,$A25)/$E25,1)) | E25: =COUNTIF('Meal Log'!$A:$A,$A25) -> 0 | F25: =IFERROR(VLOOKUP($A25,'Weight Log'!$A:$B,2,FALSE),"") | G25: =IFERROR(__xludf.DUMMYFUNCTION("IFERROR(ROUND(AVERAGE(FILTER($B$2:$B25,$A$2:$A25>=$A25-6,$B$2:$B25>0)),0),"""")"),"") | H25: =IFERROR(__xludf.DUMMYFUNCTION("IFERROR(ROUND(AVERAGE(FILTER($F$2:$F25,$A$2:$A25>=$A25-6,$F$2:$F25>0)),1),"""")"),"")
A26: ='Meal Log'!$A$2+24 -> 46220 | B26: =IF($A26="","",SUMIFS('Meal Log'!$E:$E,'Meal Log'!$A:$A,$A26)) -> 0 | C26: =IF($A26="","",SUMIFS('Meal Log'!$F:$F,'Meal Log'!$A:$A,$A26)) -> 0 | D26: =IF($E26=0,"",ROUND(SUMIFS('Meal Log'!$G:$G,'Meal Log'!$A:$A,$A26)/$E26,1)) | E26: =COUNTIF('Meal Log'!$A:$A,$A26) -> 0 | F26: =IFERROR(VLOOKUP($A26,'Weight Log'!$A:$B,2,FALSE),"") | G26: =IFERROR(__xludf.DUMMYFUNCTION("IFERROR(ROUND(AVERAGE(FILTER($B$2:$B26,$A$2:$A26>=$A26-6,$B$2:$B26>0)),0),"""")"),"") | H26: =IFERROR(__xludf.DUMMYFUNCTION("IFERROR(ROUND(AVERAGE(FILTER($F$2:$F26,$A$2:$A26>=$A26-6,$F$2:$F26>0)),1),"""")"),"")
A27: ='Meal Log'!$A$2+25 -> 46221 | B27: =IF($A27="","",SUMIFS('Meal Log'!$E:$E,'Meal Log'!$A:$A,$A27)) -> 0 | C27: =IF($A27="","",SUMIFS('Meal Log'!$F:$F,'Meal Log'!$A:$A,$A27)) -> 0 | D27: =IF($E27=0,"",ROUND(SUMIFS('Meal Log'!$G:$G,'Meal Log'!$A:$A,$A27)/$E27,1)) | E27: =COUNTIF('Meal Log'!$A:$A,$A27) -> 0 | F27: =IFERROR(VLOOKUP($A27,'Weight Log'!$A:$B,2,FALSE),"") | G27: =IFERROR(__xludf.DUMMYFUNCTION("IFERROR(ROUND(AVERAGE(FILTER($B$2:$B27,$A$2:$A27>=$A27-6,$B$2:$B27>0)),0),"""")"),"") | H27: =IFERROR(__xludf.DUMMYFUNCTION("IFERROR(ROUND(AVERAGE(FILTER($F$2:$F27,$A$2:$A27>=$A27-6,$F$2:$F27>0)),1),"""")"),"")
A28: ='Meal Log'!$A$2+26 -> 46222 | B28: =IF($A28="","",SUMIFS('Meal Log'!$E:$E,'Meal Log'!$A:$A,$A28)) -> 0 | C28: =IF($A28="","",SUMIFS('Meal Log'!$F:$F,'Meal Log'!$A:$A,$A28)) -> 0 | D28: =IF($E28=0,"",ROUND(SUMIFS('Meal Log'!$G:$G,'Meal Log'!$A:$A,$A28)/$E28,1)) | E28: =COUNTIF('Meal Log'!$A:$A,$A28) -> 0 | F28: =IFERROR(VLOOKUP($A28,'Weight Log'!$A:$B,2,FALSE),"") | G28: =IFERROR(__xludf.DUMMYFUNCTION("IFERROR(ROUND(AVERAGE(FILTER($B$2:$B28,$A$2:$A28>=$A28-6,$B$2:$B28>0)),0),"""")"),"") | H28: =IFERROR(__xludf.DUMMYFUNCTION("IFERROR(ROUND(AVERAGE(FILTER($F$2:$F28,$A$2:$A28>=$A28-6,$F$2:$F28>0)),1),"""")"),"")
A29: ='Meal Log'!$A$2+27 -> 46223 | B29: =IF($A29="","",SUMIFS('Meal Log'!$E:$E,'Meal Log'!$A:$A,$A29)) -> 0 | C29: =IF($A29="","",SUMIFS('Meal Log'!$F:$F,'Meal Log'!$A:$A,$A29)) -> 0 | D29: =IF($E29=0,"",ROUND(SUMIFS('Meal Log'!$G:$G,'Meal Log'!$A:$A,$A29)/$E29,1)) | E29: =COUNTIF('Meal Log'!$A:$A,$A29) -> 0 | F29: =IFERROR(VLOOKUP($A29,'Weight Log'!$A:$B,2,FALSE),"") | G29: =IFERROR(__xludf.DUMMYFUNCTION("IFERROR(ROUND(AVERAGE(FILTER($B$2:$B29,$A$2:$A29>=$A29-6,$B$2:$B29>0)),0),"""")"),"") | H29: =IFERROR(__xludf.DUMMYFUNCTION("IFERROR(ROUND(AVERAGE(FILTER($F$2:$F29,$A$2:$A29>=$A29-6,$F$2:$F29>0)),1),"""")"),"")
A30: ='Meal Log'!$A$2+28 -> 46224 | B30: =IF($A30="","",SUMIFS('Meal Log'!$E:$E,'Meal Log'!$A:$A,$A30)) -> 0 | C30: =IF($A30="","",SUMIFS('Meal Log'!$F:$F,'Meal Log'!$A:$A,$A30)) -> 0 | D30: =IF($E30=0,"",ROUND(SUMIFS('Meal Log'!$G:$G,'Meal Log'!$A:$A,$A30)/$E30,1)) | E30: =COUNTIF('Meal Log'!$A:$A,$A30) -> 0 | F30: =IFERROR(VLOOKUP($A30,'Weight Log'!$A:$B,2,FALSE),"") | G30: =IFERROR(__xludf.DUMMYFUNCTION("IFERROR(ROUND(AVERAGE(FILTER($B$2:$B30,$A$2:$A30>=$A30-6,$B$2:$B30>0)),0),"""")"),"") | H30: =IFERROR(__xludf.DUMMYFUNCTION("IFERROR(ROUND(AVERAGE(FILTER($F$2:$F30,$A$2:$A30>=$A30-6,$F$2:$F30>0)),1),"""")"),"")
A31: ='Meal Log'!$A$2+29 -> 46225 | B31: =IF($A31="","",SUMIFS('Meal Log'!$E:$E,'Meal Log'!$A:$A,$A31)) -> 0 | C31: =IF($A31="","",SUMIFS('Meal Log'!$F:$F,'Meal Log'!$A:$A,$A31)) -> 0 | D31: =IF($E31=0,"",ROUND(SUMIFS('Meal Log'!$G:$G,'Meal Log'!$A:$A,$A31)/$E31,1)) | E31: =COUNTIF('Meal Log'!$A:$A,$A31) -> 0 | F31: =IFERROR(VLOOKUP($A31,'Weight Log'!$A:$B,2,FALSE),"") | G31: =IFERROR(__xludf.DUMMYFUNCTION("IFERROR(ROUND(AVERAGE(FILTER($B$2:$B31,$A$2:$A31>=$A31-6,$B$2:$B31>0)),0),"""")"),"") | H31: =IFERROR(__xludf.DUMMYFUNCTION("IFERROR(ROUND(AVERAGE(FILTER($F$2:$F31,$A$2:$A31>=$A31-6,$F$2:$F31>0)),1),"""")"),"")
A32: ='Meal Log'!$A$2+30 -> 46226 | B32: =IF($A32="","",SUMIFS('Meal Log'!$E:$E,'Meal Log'!$A:$A,$A32)) -> 0 | C32: =IF($A32="","",SUMIFS('Meal Log'!$F:$F,'Meal Log'!$A:$A,$A32)) -> 0 | D32: =IF($E32=0,"",ROUND(SUMIFS('Meal Log'!$G:$G,'Meal Log'!$A:$A,$A32)/$E32,1)) | E32: =COUNTIF('Meal Log'!$A:$A,$A32) -> 0 | F32: =IFERROR(VLOOKUP($A32,'Weight Log'!$A:$B,2,FALSE),"") | G32: =IFERROR(__xludf.DUMMYFUNCTION("IFERROR(ROUND(AVERAGE(FILTER($B$2:$B32,$A$2:$A32>=$A32-6,$B$2:$B32>0)),0),"""")"),"") | H32: =IFERROR(__xludf.DUMMYFUNCTION("IFERROR(ROUND(AVERAGE(FILTER($F$2:$F32,$A$2:$A32>=$A32-6,$F$2:$F32>0)),1),"""")"),"")
A33: ='Meal Log'!$A$2+31 -> 46227 | B33: =IF($A33="","",SUMIFS('Meal Log'!$E:$E,'Meal Log'!$A:$A,$A33)) -> 0 | C33: =IF($A33="","",SUMIFS('Meal Log'!$F:$F,'Meal Log'!$A:$A,$A33)) -> 0 | D33: =IF($E33=0,"",ROUND(SUMIFS('Meal Log'!$G:$G,'Meal Log'!$A:$A,$A33)/$E33,1)) | E33: =COUNTIF('Meal Log'!$A:$A,$A33) -> 0 | F33: =IFERROR(VLOOKUP($A33,'Weight Log'!$A:$B,2,FALSE),"") | G33: =IFERROR(__xludf.DUMMYFUNCTION("IFERROR(ROUND(AVERAGE(FILTER($B$2:$B33,$A$2:$A33>=$A33-6,$B$2:$B33>0)),0),"""")"),"") | H33: =IFERROR(__xludf.DUMMYFUNCTION("IFERROR(ROUND(AVERAGE(FILTER($F$2:$F33,$A$2:$A33>=$A33-6,$F$2:$F33>0)),1),"""")"),"")
A34: ='Meal Log'!$A$2+32 -> 46228 | B34: =IF($A34="","",SUMIFS('Meal Log'!$E:$E,'Meal Log'!$A:$A,$A34)) -> 0 | C34: =IF($A34="","",SUMIFS('Meal Log'!$F:$F,'Meal Log'!$A:$A,$A34)) -> 0 | D34: =IF($E34=0,"",ROUND(SUMIFS('Meal Log'!$G:$G,'Meal Log'!$A:$A,$A34)/$E34,1)) | E34: =COUNTIF('Meal Log'!$A:$A,$A34) -> 0 | F34: =IFERROR(VLOOKUP($A34,'Weight Log'!$A:$B,2,FALSE),"") | G34: =IFERROR(__xludf.DUMMYFUNCTION("IFERROR(ROUND(AVERAGE(FILTER($B$2:$B34,$A$2:$A34>=$A34-6,$B$2:$B34>0)),0),"""")"),"") | H34: =IFERROR(__xludf.DUMMYFUNCTION("IFERROR(ROUND(AVERAGE(FILTER($F$2:$F34,$A$2:$A34>=$A34-6,$F$2:$F34>0)),1),"""")"),"")
A35: ='Meal Log'!$A$2+33 -> 46229 | B35: =IF($A35="","",SUMIFS('Meal Log'!$E:$E,'Meal Log'!$A:$A,$A35)) -> 0 | C35: =IF($A35="","",SUMIFS('Meal Log'!$F:$F,'Meal Log'!$A:$A,$A35)) -> 0 | D35: =IF($E35=0,"",ROUND(SUMIFS('Meal Log'!$G:$G,'Meal Log'!$A:$A,$A35)/$E35,1)) | E35: =COUNTIF('Meal Log'!$A:$A,$A35) -> 0 | F35: =IFERROR(VLOOKUP($A35,'Weight Log'!$A:$B,2,FALSE),"") | G35: =IFERROR(__xludf.DUMMYFUNCTION("IFERROR(ROUND(AVERAGE(FILTER($B$2:$B35,$A$2:$A35>=$A35-6,$B$2:$B35>0)),0),"""")"),"") | H35: =IFERROR(__xludf.DUMMYFUNCTION("IFERROR(ROUND(AVERAGE(FILTER($F$2:$F35,$A$2:$A35>=$A35-6,$F$2:$F35>0)),1),"""")"),"")
A36: ='Meal Log'!$A$2+34 -> 46230 | B36: =IF($A36="","",SUMIFS('Meal Log'!$E:$E,'Meal Log'!$A:$A,$A36)) -> 0 | C36: =IF($A36="","",SUMIFS('Meal Log'!$F:$F,'Meal Log'!$A:$A,$A36)) -> 0 | D36: =IF($E36=0,"",ROUND(SUMIFS('Meal Log'!$G:$G,'Meal Log'!$A:$A,$A36)/$E36,1)) | E36: =COUNTIF('Meal Log'!$A:$A,$A36) -> 0 | F36: =IFERROR(VLOOKUP($A36,'Weight Log'!$A:$B,2,FALSE),"") | G36: =IFERROR(__xludf.DUMMYFUNCTION("IFERROR(ROUND(AVERAGE(FILTER($B$2:$B36,$A$2:$A36>=$A36-6,$B$2:$B36>0)),0),"""")"),"") | H36: =IFERROR(__xludf.DUMMYFUNCTION("IFERROR(ROUND(AVERAGE(FILTER($F$2:$F36,$A$2:$A36>=$A36-6,$F$2:$F36>0)),1),"""")"),"")
A37: ='Meal Log'!$A$2+35 -> 46231 | B37: =IF($A37="","",SUMIFS('Meal Log'!$E:$E,'Meal Log'!$A:$A,$A37)) -> 0 | C37: =IF($A37="","",SUMIFS('Meal Log'!$F:$F,'Meal Log'!$A:$A,$A37)) -> 0 | D37: =IF($E37=0,"",ROUND(SUMIFS('Meal Log'!$G:$G,'Meal Log'!$A:$A,$A37)/$E37,1)) | E37: =COUNTIF('Meal Log'!$A:$A,$A37) -> 0 | F37: =IFERROR(VLOOKUP($A37,'Weight Log'!$A:$B,2,FALSE),"") | G37: =IFERROR(__xludf.DUMMYFUNCTION("IFERROR(ROUND(AVERAGE(FILTER($B$2:$B37,$A$2:$A37>=$A37-6,$B$2:$B37>0)),0),"""")"),"") | H37: =IFERROR(__xludf.DUMMYFUNCTION("IFERROR(ROUND(AVERAGE(FILTER($F$2:$F37,$A$2:$A37>=$A37-6,$F$2:$F37>0)),1),"""")"),"")
A38: ='Meal Log'!$A$2+36 -> 46232 | B38: =IF($A38="","",SUMIFS('Meal Log'!$E:$E,'Meal Log'!$A:$A,$A38)) -> 0 | C38: =IF($A38="","",SUMIFS('Meal Log'!$F:$F,'Meal Log'!$A:$A,$A38)) -> 0 | D38: =IF($E38=0,"",ROUND(SUMIFS('Meal Log'!$G:$G,'Meal Log'!$A:$A,$A38)/$E38,1)) | E38: =COUNTIF('Meal Log'!$A:$A,$A38) -> 0 | F38: =IFERROR(VLOOKUP($A38,'Weight Log'!$A:$B,2,FALSE),"") | G38: =IFERROR(__xludf.DUMMYFUNCTION("IFERROR(ROUND(AVERAGE(FILTER($B$2:$B38,$A$2:$A38>=$A38-6,$B$2:$B38>0)),0),"""")"),"") | H38: =IFERROR(__xludf.DUMMYFUNCTION("IFERROR(ROUND(AVERAGE(FILTER($F$2:$F38,$A$2:$A38>=$A38-6,$F$2:$F38>0)),1),"""")"),"")
A39: ='Meal Log'!$A$2+37 -> 46233 | B39: =IF($A39="","",SUMIFS('Meal Log'!$E:$E,'Meal Log'!$A:$A,$A39)) -> 0 | C39: =IF($A39="","",SUMIFS('Meal Log'!$F:$F,'Meal Log'!$A:$A,$A39)) -> 0 | D39: =IF($E39=0,"",ROUND(SUMIFS('Meal Log'!$G:$G,'Meal Log'!$A:$A,$A39)/$E39,1)) | E39: =COUNTIF('Meal Log'!$A:$A,$A39) -> 0 | F39: =IFERROR(VLOOKUP($A39,'Weight Log'!$A:$B,2,FALSE),"") | G39: =IFERROR(__xludf.DUMMYFUNCTION("IFERROR(ROUND(AVERAGE(FILTER($B$2:$B39,$A$2:$A39>=$A39-6,$B$2:$B39>0)),0),"""")"),"") | H39: =IFERROR(__xludf.DUMMYFUNCTION("IFERROR(ROUND(AVERAGE(FILTER($F$2:$F39,$A$2:$A39>=$A39-6,$F$2:$F39>0)),1),"""")"),"")
A40: ='Meal Log'!$A$2+38 -> 46234 | B40: =IF($A40="","",SUMIFS('Meal Log'!$E:$E,'Meal Log'!$A:$A,$A40)) -> 0 | C40: =IF($A40="","",SUMIFS('Meal Log'!$F:$F,'Meal Log'!$A:$A,$A40)) -> 0 | D40: =IF($E40=0,"",ROUND(SUMIFS('Meal Log'!$G:$G,'Meal Log'!$A:$A,$A40)/$E40,1)) | E40: =COUNTIF('Meal Log'!$A:$A,$A40) -> 0 | F40: =IFERROR(VLOOKUP($A40,'Weight Log'!$A:$B,2,FALSE),"") | G40: =IFERROR(__xludf.DUMMYFUNCTION("IFERROR(ROUND(AVERAGE(FILTER($B$2:$B40,$A$2:$A40>=$A40-6,$B$2:$B40>0)),0),"""")"),"") | H40: =IFERROR(__xludf.DUMMYFUNCTION("IFERROR(ROUND(AVERAGE(FILTER($F$2:$F40,$A$2:$A40>=$A40-6,$F$2:$F40>0)),1),"""")"),"")
...

Sheet Weight Log
A1: Date | B1: Weight | C1: Goal Weight | D1: Notes
A2: 46196 | B2: 186 | C2: 170 | D2: starting point
A3: 46197 | B3: 185
A4: 46198 | B4: 184
A5: 46200 | B5: 181.8

Sheet Instructions
A1: Food Tracker Instructions
A3: 1 | B3: Import this .xlsx into Google Sheets.
A4: 2 | B4: On Foods, define nicknames and calories once, e.g., Blueberry Protein Shake.
A5: 3 | B5: On Meal Log, enter Date, Meal, Food, and Quantity after each meal from your phone.
A6: 4 | B6: Use decimal quantities for partial servings, e.g., 0.5 for half a cup of mixed nuts/raisins.
A7: 5 | B7: If a food is missing, add it to Foods first; the Meal Log will then calculate automatically.
A8: 6 | B8: Update Weight Log whenever you weigh yourself.
A9: 7 | B9: Use Daily Summary and Dashboard to watch weekly calorie average, protein, nutrition score, and weight trend.
A11: Note | B11: Formulas use common Google Sheets/Excel functions such as VLOOKUP, SUMIFS, COUNTIFS, FILTER, LOOKUP, and IFERROR.
A12: Tip | B12: For faster phone entry, create a Google Form later with Date, Meal, Food, Quantity fields connected to Meal Log.
A13: Target | B13: Initial default targets: 2,000 calories/day, 100g protein/day, nutrition score 7+. Adjust based on your weight trend.
